<?xml version="1.0"?>
<!--
  Robot: cora
  Generated by: LinkForge v1.2.0
  https://github.com/arounamounchili/linkforge
  Date: 2026-01-27 16:13:53
-->
<robot name="cora">
  <!-- Materials -->
  <material name="baselink_parts_material">
    <color rgba="1 1 1 1" />
  </material>
  <material name="baselink_parts_material_003">
    <color rgba="0.5466 0.5466 0.5466 1" />
  </material>
  <material name="l2_parts_material">
    <color rgba="0.027196 0.029506 0.032663 0.950503" />
  </material>
  <material name="l3_parts_material">
    <color rgba="0.043541 0.047185 0.052154 0.972899" />
  </material>
  <material name="l4_parts_material">
    <color rgba="0.02527 0.026559 0.028049 0.933148" />
  </material>
  <material name="l5_parts_material">
    <color rgba="0.027275 0.02868 0.030305 0.933148" />
  </material>
  <material name="endeffector_parts_material">
    <color rgba="0 0.093059 1 1" />
  </material>
  <material name="gripper_body_parts_material">
    <color rgba="0.081176 0.081176 0.081176 1" />
  </material>
  <material name="gripper_fingers_parts_material">
    <color rgba="0 0.093059 1 1" />
  </material>
  <material name="gripper_fingers_2_parts_material">
    <color rgba="0 0.093059 1 1" />
  </material>
  <!-- Links -->
  <link name="base_link">
    <inertial>
      <mass value="0" />
      <inertia ixx="0" ixy="0" ixz="0" iyy="0" iyz="0" izz="0" />
    </inertial>
  </link>
  <link name="baselink">
    <visual>
      <origin xyz="0 -0.000004 0.117444" rpy="0 0 0" />
      <geometry>
        <mesh filename="meshes/baselink_visual.stl" />
      </geometry>
      <material name="baselink_parts_material" />
    </visual>
    <collision>
      <origin xyz="0 -0.000004 0.117444" rpy="0 0 0" />
      <geometry>
        <mesh filename="meshes/baselink_collision.stl" />
      </geometry>
    </collision>
    <inertial>
      <origin xyz="0 -0.000004 0.117444" rpy="0 0 0" />
      <mass value="0.24516" />
      <inertia ixx="0.000324" ixy="0" ixz="0" iyy="0.000312" iyz="0" izz="0.000593" />
    </inertial>
  </link>
  <link name="l1">
    <visual>
      <origin xyz="0.019193 0.011081 -0.081454" rpy="3.14159 0.000001 0.523599" />
      <geometry>
        <mesh filename="meshes/l1_visual.stl" />
      </geometry>
      <material name="baselink_parts_material_003" />
    </visual>
    <collision>
      <origin xyz="0.019193 0.011081 -0.081454" rpy="3.14159 0 0.523599" />
      <geometry>
        <mesh filename="meshes/l1_collision.stl" />
      </geometry>
    </collision>
    <inertial>
      <origin xyz="0.019193 0.011081 -0.081454" rpy="0 0 0" />
      <mass value="0.953925" />
      <inertia ixx="0.003883" ixy="-0.000254" ixz="0.000202" iyy="0.004176" iyz="0.000116" izz="0.003427" />
    </inertial>
  </link>
  <link name="l2">
    <visual>
      <origin xyz="0.194271 0.112163 -0.082967" rpy="-0.523599 1.570793 0" />
      <geometry>
        <mesh filename="meshes/l2_visual.stl" />
      </geometry>
      <material name="l2_parts_material" />
    </visual>
    <collision>
      <origin xyz="0.194271 0.112163 -0.082967" rpy="-0.523599 1.570793 0" />
      <geometry>
        <mesh filename="meshes/l2_collision.stl" />
      </geometry>
    </collision>
    <inertial>
      <origin xyz="0.194271 0.112163 -0.082967" rpy="0 0 0" />
      <mass value="2.493" />
      <inertia ixx="0.030231" ixy="-0.037664" ixz="-0.00003" iyy="0.073675" iyz="-0.000017" izz="0.093637" />
    </inertial>
  </link>
  <link name="l3">
    <visual>
      <origin xyz="0 -0.171257 -0.079261" rpy="1.5708 -1.570793 0" />
      <geometry>
        <mesh filename="meshes/l3_visual.stl" />
      </geometry>
      <material name="l3_parts_material" />
    </visual>
    <collision>
      <origin xyz="0 -0.171257 -0.079261" rpy="1.5708 -1.570793 0" />
      <geometry>
        <mesh filename="meshes/l3_collision.stl" />
      </geometry>
    </collision>
    <inertial>
      <origin xyz="0 -0.171257 -0.079261" rpy="0 0 0" />
      <mass value="0.938652" />
      <inertia ixx="0.019768" ixy="0" ixz="0" iyy="0.002358" iyz="-0.001688" izz="0.019246" />
    </inertial>
  </link>
  <link name="l4">
    <visual>
      <origin xyz="0 0.006377 -0.055895" rpy="-1.5708 1.570793 0" />
      <geometry>
        <mesh filename="meshes/l4_visual.stl" />
      </geometry>
      <material name="l4_parts_material" />
    </visual>
    <collision>
      <origin xyz="0 0.006377 -0.055895" rpy="-1.5708 1.570793 0" />
      <geometry>
        <mesh filename="meshes/l4_collision.stl" />
      </geometry>
    </collision>
    <inertial>
      <origin xyz="0 0.006377 -0.055895" rpy="0 0 0" />
      <mass value="0.380512" />
      <inertia ixx="0.001108" ixy="0" ixz="0" iyy="0.000909" iyz="0.000071" izz="0.000978" />
    </inertial>
  </link>
  <link name="l5">
    <visual>
      <origin xyz="0 0.006377 -0.055895" rpy="0.000003 3.141593 1.570793" />
      <geometry>
        <mesh filename="meshes/l5_visual.stl" />
      </geometry>
      <material name="l5_parts_material" />
    </visual>
    <collision>
      <origin xyz="0 0.006377 -0.055895" rpy="0.000003 3.141593 1.570793" />
      <geometry>
        <mesh filename="meshes/l5_collision.stl" />
      </geometry>
    </collision>
    <inertial>
      <origin xyz="0 0.006377 -0.055895" rpy="0 0 0" />
      <mass value="0.380512" />
      <inertia ixx="0.001108" ixy="0" ixz="0" iyy="0.000909" iyz="0.000071" izz="0.000978" />
    </inertial>
  </link>
  <link name="endeffector">
    <visual>
      <origin xyz="1.17217 0 -0.083" rpy="0 -1.570793 0" />
      <geometry>
        <mesh filename="meshes/endeffector_visual.stl" />
      </geometry>
      <material name="endeffector_parts_material" />
    </visual>
    <collision>
      <origin xyz="1.17217 0 -0.083" rpy="0 -1.570793 0" />
      <geometry>
        <mesh filename="meshes/endeffector_collision.stl" />
      </geometry>
    </collision>
    <inertial>
      <mass value="0" />
      <inertia ixx="0" ixy="0" ixz="0" iyy="0" iyz="0" izz="0" />
    </inertial>
  </link>
  <link name="gripper_body_004">
    <visual>
      <origin xyz="0 -1.17217 -0.059" rpy="-1.5708 -1.570793 0" />
      <geometry>
        <mesh filename="meshes/gripper_body_004_visual.stl" />
      </geometry>
      <material name="gripper_body_parts_material" />
    </visual>
    <collision>
      <origin xyz="0 -1.17217 -0.059" rpy="-1.5708 -1.570793 0" />
      <geometry>
        <mesh filename="meshes/gripper_body_004_collision.stl" />
      </geometry>
    </collision>
    <inertial>
      <mass value="0" />
      <inertia ixx="0" ixy="0" ixz="0" iyy="0" iyz="0" izz="0" />
    </inertial>
  </link>
  <link name="Gripper">
    <inertial>
      <mass value="0" />
      <inertia ixx="0.000001" ixy="0" ixz="0" iyy="0.000001" iyz="0" izz="0.000001" />
    </inertial>
  </link>
  <link name="Camera_001">
    <inertial>
      <mass value="0" />
      <inertia ixx="0.000001" ixy="0" ixz="0" iyy="0.000001" iyz="0" izz="0.000001" />
    </inertial>
  </link>
  <link name="gripper_fingers_004">
    <visual>
      <origin xyz="1.17667 0.0095 0.07" rpy="-1.5708 0 1.5708" />
      <geometry>
        <mesh filename="meshes/gripper_fingers_004_visual.stl" />
      </geometry>
      <material name="gripper_fingers_parts_material" />
    </visual>
    <collision>
      <origin xyz="1.17667 0.0095 0.07" rpy="-1.5708 0 1.5708" />
      <geometry>
        <mesh filename="meshes/gripper_fingers_004_collision.stl" />
      </geometry>
    </collision>
    <inertial>
      <mass value="0" />
      <inertia ixx="0" ixy="0" ixz="0" iyy="0" iyz="0" izz="0" />
    </inertial>
  </link>
  <link name="gripper_fingers_2">
    <visual>
      <origin xyz="-1.16767 0.0095 0.07" rpy="1.5708 0 1.5708" />
      <geometry>
        <mesh filename="meshes/gripper_fingers_2_visual.stl" />
      </geometry>
      <material name="gripper_fingers_2_parts_material" />
    </visual>
    <collision>
      <origin xyz="-1.16767 0.0095 0.07" rpy="1.5708 0 1.5708" />
      <geometry>
        <mesh filename="meshes/gripper_fingers_2_collision.stl" />
      </geometry>
    </collision>
    <inertial>
      <mass value="0" />
      <inertia ixx="0" ixy="0" ixz="0" iyy="0" iyz="0" izz="0" />
    </inertial>
  </link>
  <!-- Joints -->
  <joint name="base_link_to_baselink" type="fixed">
    <parent link="base_link" />
    <child link="baselink" />
  </joint>
  <joint name="J1" type="revolute">
    <origin xyz="0 0 0.139" rpy="-3.14159 0 0.523599" />
    <parent link="baselink" />
    <child link="l1" />
    <axis xyz="0 0 1" />
    <limit effort="10" velocity="2" lower="-3.14" upper="3.14" />
  </joint>
  <joint name="J2" type="revolute">
    <origin xyz="0.090067 0.052 -0.088" rpy="1.570793 2.094393 -1.047192" />
    <parent link="l1" />
    <child link="l2" />
    <axis xyz="0 0 1" />
    <limit effort="10" velocity="2" lower="-3.14" upper="3.14" />
  </joint>
  <joint name="J3" type="revolute">
    <origin xyz="0.393176 0.227 0.002" rpy="-3.14159 0 -1.0472" />
    <parent link="l2" />
    <child link="l3" />
    <axis xyz="0 0 1" />
    <limit effort="10" velocity="2" lower="-3.14" upper="3.14" />
  </joint>
  <joint name="J4" type="revolute">
    <origin xyz="0 -0.335 -0.013833" rpy="-3.14159 0 0" />
    <parent link="l3" />
    <child link="l4" />
    <axis xyz="0 0 1" />
    <limit effort="10" velocity="2" lower="-3.14" upper="3.14" />
  </joint>
  <joint name="J5" type="revolute">
    <origin xyz="0 0.081167 -0.075" rpy="1.5708 0 0" />
    <parent link="l4" />
    <child link="l5" />
    <axis xyz="0 0 1" />
    <limit effort="10" velocity="2" lower="-3.14" upper="3.14" />
  </joint>
  <joint name="J6" type="revolute">
    <origin xyz="0 0.080167 -0.075" rpy="1.5708 -1.570793 0" />
    <parent link="l5" />
    <child link="endeffector" />
    <axis xyz="0 0 1" />
    <limit effort="10" velocity="2" lower="-3.14" upper="3.14" />
  </joint>
  <joint name="GripperFix" type="fixed">
    <origin xyz="0 0 -0.024" rpy="0 0 1.5708" />
    <parent link="endeffector" />
    <child link="gripper_body_004" />
  </joint>
  <joint name="Gripper_frame" type="fixed">
    <origin xyz="0 0 -0.112" rpy="-3.14159 0 0" />
    <parent link="gripper_body_004" />
    <child link="Gripper" />
  </joint>
  <joint name="Camera_frame" type="fixed">
    <origin xyz="0.016614 0.0515 -0.046096" rpy="0.000003 3.141593 -0.000003" />
    <parent link="gripper_body_004" />
    <child link="Camera_001" />
  </joint>
  <joint name="Finger1" type="prismatic">
    <origin xyz="0.07 0.0045 -0.0685" rpy="1.5708 0 -1.5708" />
    <parent link="gripper_body_004" />
    <child link="gripper_fingers_004" />
    <axis xyz="0 0 1" />
    <limit effort="10" velocity="10" lower="0" upper="0.0385" />
  </joint>
  <joint name="Finger2" type="prismatic">
    <origin xyz="-0.07 -0.0045 -0.0685" rpy="1.5708 0 1.5708" />
    <parent link="gripper_body_004" />
    <child link="gripper_fingers_2" />
    <axis xyz="0 0 1" />
    <limit effort="10" velocity="10" lower="0" upper="0.0385" />
    <mimic joint="Finger1" />
  </joint>
</robot>